[32mINFO    [0m BasePage:base_page.py:66 Navigating to: http://localhost:5173/
[32mINFO    [0m TestBlogDetailDebug:test_blog_detail_debug.py:214 Homepage title: SWP Group 3
[32mINFO    [0m BasePage:base_page.py:66 Navigating to: http://localhost:5173/blogs
[31m[1mERROR   [0m TestBlogDetailDebug:test_blog_detail_debug.py:226 Browser error: http://localhost:5173/favicon.ico - Failed to load resource: the server responded with a status of 404 (Not Found)
[32mINFO    [0m TestBlogDetailDebug:test_blog_detail_debug.py:246 âœ… Frontend-backend connection test completed
[32mINFO    [0m utils.driver_manager:driver_manager.py:190 WebDriver quit successfully
[33mWARNING [0m urllib3.connectionpool:connectionpool.py:868 Retrying (Retry(total=2, connect=None, read=None, redirect=None, status=None)) after connection broken by 'NewConnectionError('<urllib3.connection.HTTPConnection object at 0x000001F2C26F6270>: Failed to establish a new connection: [WinError 10061] No connection could be made because the target machine actively refused it')': /session/2b945bbe2cbb9e43045ba50a45c4b38d/element
[33mWARNING [0m urllib3.connectionpool:connectionpool.py:868 Retrying (Retry(total=1, connect=None, read=None, redirect=None, status=None)) after connection broken by 'NewConnectionError('<urllib3.connection.HTTPConnection object at 0x000001F2C26F66C0>: Failed to establish a new connection: [WinError 10061] No connection could be made because the target machine actively refused it')': /session/2b945bbe2cbb9e43045ba50a45c4b38d/element
[33mWARNING [0m urllib3.connectionpool:connectionpool.py:868 Retrying (Retry(total=0, connect=None, read=None, redirect=None, status=None)) after connection broken by 'NewConnectionError('<urllib3.connection.HTTPConnection object at 0x000001F2C26F68D0>: Failed to establish a new connection: [WinError 10061] No connection could be made because the target machine actively refused it')': /session/2b945bbe2cbb9e43045ba50a45c4b38d/element
[31m[1mERROR   [0m LoginPage:login_page.py:414 Exception during logout: HTTPConnectionPool(host='localhost', port=52675): Max retries exceeded with url: /session/2b945bbe2cbb9e43045ba50a45c4b38d/element (Caused by NewConnectionError('<urllib3.connection.HTTPConnection object at 0x000001F2C26F6AE0>: Failed to establish a new connection: [WinError 10061] No connection could be made because the target machine actively refused it'))
[32mINFO    [0m TestBlogDetailDebug:test_blog_detail_debug.py:36 âœ… Debug test completed: test_debug_frontend_backend_connection