[32mINFO    [0m TestBlogCRUD:test_blog_crud.py:29 
üß™ Starting test: test_authenticated_users_can_read_blogs
[32mINFO    [0m WDM:logger.py:11 ====== WebDriver manager ======
[32mINFO    [0m WDM:logger.py:11 Get LATEST edgedriver version for Edge 137.0.3296
[32mINFO    [0m WDM:logger.py:11 Get LATEST edgedriver version for Edge 137.0.3296
[32mINFO    [0m WDM:logger.py:11 Driver [C:\Users\Dell\.wdm\drivers\edgedriver\win64\137.0.3296.93\msedgedriver.exe] found in cache
[32mINFO    [0m utils.driver_manager:driver_manager.py:93 Edge WebDriver created successfully
[32mINFO    [0m utils.driver_manager:driver_manager.py:110 Driver configured with timeouts - Implicit: 3s, Page load: 10s, Explicit: 8s
[32mINFO    [0m LoginPage:login_page.py:308 Attempting login with email: staff1@gencare.com
[32mINFO    [0m LoginPage:base_page.py:66 Navigating to: http://localhost:5173/
[32mINFO    [0m LoginPage:base_page.py:134 Clicked element: ('xpath', "//button[contains(text(), 'ƒêƒÉng nh·∫≠p')]")
[32mINFO    [0m LoginPage:login_page.py:75 Login modal opened successfully
[32mINFO    [0m LoginPage:base_page.py:158 Typed text into ('name', 'email'): staff1@gencare.com
[32mINFO    [0m LoginPage:base_page.py:158 Typed text into ('name', 'password'): password
[32mINFO    [0m LoginPage:base_page.py:134 Clicked element: ('xpath', "//button[@type='submit' and contains(text(), 'ƒêƒÉng nh·∫≠p')]")
[31m[1mERROR   [0m LoginPage:login_page.py:342 Login failed:
[32mINFO    [0m utils.driver_manager:driver_manager.py:190 WebDriver quit successfully
[33mWARNING [0m urllib3.connectionpool:connectionpool.py:868 Retrying (Retry(total=2, connect=None, read=None, redirect=None, status=None)) after connection broken by 'NewConnectionError('<urllib3.connection.HTTPConnection object at 0x000001B001B78470>: Failed to establish a new connection: [WinError 10061] No connection could be made because the target machine actively refused it')': /session/ac7d9a0e718cf715542ffe439a42fb8d/element
[33mWARNING [0m urllib3.connectionpool:connectionpool.py:868 Retrying (Retry(total=1, connect=None, read=None, redirect=None, status=None)) after connection broken by 'NewConnectionError('<urllib3.connection.HTTPConnection object at 0x000001B001B7AF60>: Failed to establish a new connection: [WinError 10061] No connection could be made because the target machine actively refused it')': /session/ac7d9a0e718cf715542ffe439a42fb8d/element
[33mWARNING [0m urllib3.connectionpool:connectionpool.py:868 Retrying (Retry(total=0, connect=None, read=None, redirect=None, status=None)) after connection broken by 'NewConnectionError('<urllib3.connection.HTTPConnection object at 0x000001B001B7B590>: Failed to establish a new connection: [WinError 10061] No connection could be made because the target machine actively refused it')': /session/ac7d9a0e718cf715542ffe439a42fb8d/element
[31m[1mERROR   [0m LoginPage:login_page.py:414 Exception during logout: HTTPConnectionPool(host='localhost', port=52505): Max retries exceeded with url: /session/ac7d9a0e718cf715542ffe439a42fb8d/element (Caused by NewConnectionError('<urllib3.connection.HTTPConnection object at 0x000001B001B7B860>: Failed to establish a new connection: [WinError 10061] No connection could be made because the target machine actively refused it'))
[32mINFO    [0m TestBlogCRUD:test_blog_crud.py:37 ‚úÖ Test completed: test_authenticated_users_can_read_blogs