[32mINFO    [0m LoginPage:login_page.py:308 Attempting login with email: admin1@gencare.com
[32mINFO    [0m LoginPage:base_page.py:66 Navigating to: http://localhost:5173/
[32mINFO    [0m LoginPage:base_page.py:134 Clicked element: ('xpath', "//button[contains(text(), 'ƒêƒÉng nh·∫≠p')]")
[32mINFO    [0m LoginPage:login_page.py:75 Login modal opened successfully
[32mINFO    [0m LoginPage:base_page.py:158 Typed text into ('name', 'email'): admin1@gencare.com
[32mINFO    [0m LoginPage:base_page.py:158 Typed text into ('name', 'password'): password
[32mINFO    [0m LoginPage:base_page.py:134 Clicked element: ('xpath', "//button[@type='submit' and contains(text(), 'ƒêƒÉng nh·∫≠p')]")
[31m[1mERROR   [0m LoginPage:login_page.py:342 Login failed:
[32mINFO    [0m utils.driver_manager:driver_manager.py:190 WebDriver quit successfully
[33mWARNING [0m urllib3.connectionpool:connectionpool.py:868 Retrying (Retry(total=2, connect=None, read=None, redirect=None, status=None)) after connection broken by 'NewConnectionError('<urllib3.connection.HTTPConnection object at 0x0000021B0495AE10>: Failed to establish a new connection: [WinError 10061] No connection could be made because the target machine actively refused it')': /session/f6a85cc5d24bf1317fb1485f475fcaee/element
[33mWARNING [0m urllib3.connectionpool:connectionpool.py:868 Retrying (Retry(total=1, connect=None, read=None, redirect=None, status=None)) after connection broken by 'NewConnectionError('<urllib3.connection.HTTPConnection object at 0x0000021B0495B140>: Failed to establish a new connection: [WinError 10061] No connection could be made because the target machine actively refused it')': /session/f6a85cc5d24bf1317fb1485f475fcaee/element
[33mWARNING [0m urllib3.connectionpool:connectionpool.py:868 Retrying (Retry(total=0, connect=None, read=None, redirect=None, status=None)) after connection broken by 'NewConnectionError('<urllib3.connection.HTTPConnection object at 0x0000021B0495B380>: Failed to establish a new connection: [WinError 10061] No connection could be made because the target machine actively refused it')': /session/f6a85cc5d24bf1317fb1485f475fcaee/element
[31m[1mERROR   [0m LoginPage:login_page.py:414 Exception during logout: HTTPConnectionPool(host='localhost', port=53367): Max retries exceeded with url: /session/f6a85cc5d24bf1317fb1485f475fcaee/element (Caused by NewConnectionError('<urllib3.connection.HTTPConnection object at 0x0000021B0495B590>: Failed to establish a new connection: [WinError 10061] No connection could be made because the target machine actively refused it'))
[32mINFO    [0m TestBlogCRUD:test_blog_crud.py:37 ‚úÖ Test completed: test_authorized_roles_can_create_blogs